2025-07-03 22:24:02,697 - ERROR - error - Error in place_order: cannot access local variable 'validate_user_order_permissions' where it is not associated with a value
Traceback (most recent call last):
  File "C:\Users\Dhanush\FASTAPI\app\api\v1\endpoints\orders.py", line 329, in place_order
    validate_user_order_permissions(current_user, symbol, order_type, quantity),
    ^^^^^^^^^^^^^^^^^^^^^^^^^^^^^^^
UnboundLocalError: cannot access local variable 'validate_user_order_permissions' where it is not associated with a value
2025-07-03 22:27:04,573 - ERROR - error - Error in place_order: Failed to process order: Margin calculation failed
Traceback (most recent call last):
  File "C:\Users\Dhanush\FASTAPI\app\services\order_processing.py", line 260, in process_new_order_ultra_optimized
    raise OrderProcessingError("Margin calculation failed")
app.services.order_processing.OrderProcessingError: Margin calculation failed

During handling of the above exception, another exception occurred:

Traceback (most recent call last):
  File "C:\Users\Dhanush\FASTAPI\app\api\v1\endpoints\orders.py", line 380, in place_order
    processed_order_data = await process_new_order(
                           ^^^^^^^^^^^^^^^^^^^^^^^^
    ...<6 lines>...
    )
    ^
  File "C:\Users\Dhanush\FASTAPI\app\services\order_processing.py", line 343, in process_new_order_ultra_optimized
    raise OrderProcessingError(f"Failed to process order: {str(e)}")
app.services.order_processing.OrderProcessingError: Failed to process order: Margin calculation failed
2025-07-03 22:28:17,049 - ERROR - error - Error in place_order: Failed to process order: Margin calculation failed
Traceback (most recent call last):
  File "C:\Users\Dhanush\FASTAPI\app\services\order_processing.py", line 260, in process_new_order_ultra_optimized
    raise OrderProcessingError("Margin calculation failed")
app.services.order_processing.OrderProcessingError: Margin calculation failed

During handling of the above exception, another exception occurred:

Traceback (most recent call last):
  File "C:\Users\Dhanush\FASTAPI\app\api\v1\endpoints\orders.py", line 380, in place_order
    processed_order_data = await process_new_order(
                           ^^^^^^^^^^^^^^^^^^^^^^^^
    ...<6 lines>...
    )
    ^
  File "C:\Users\Dhanush\FASTAPI\app\services\order_processing.py", line 343, in process_new_order_ultra_optimized
    raise OrderProcessingError(f"Failed to process order: {str(e)}")
app.services.order_processing.OrderProcessingError: Failed to process order: Margin calculation failed
2025-07-03 22:31:28,151 - ERROR - error - Error in place_order: 'status' is required and must be a string of length 10-30.
Traceback (most recent call last):
  File "C:\Users\Dhanush\FASTAPI\app\api\v1\endpoints\orders.py", line 413, in place_order
    new_order = await crud_order.create_user_order(db=db, order_data=order_create_data.dict())
                ^^^^^^^^^^^^^^^^^^^^^^^^^^^^^^^^^^^^^^^^^^^^^^^^^^^^^^^^^^^^^^^^^^^^^^^^^^^^^^
  File "C:\Users\Dhanush\FASTAPI\app\crud\crud_order.py", line 359, in create_user_order
    raise e
  File "C:\Users\Dhanush\FASTAPI\app\crud\crud_order.py", line 327, in create_user_order
    raise ValueError("'status' is required and must be a string of length 10-30.")
ValueError: 'status' is required and must be a string of length 10-30.
2025-07-03 22:35:52,858 - ERROR - error - Error in place_order: cannot access local variable 'update_user_cache' where it is not associated with a value
Traceback (most recent call last):
  File "C:\Users\Dhanush\FASTAPI\app\api\v1\endpoints\orders.py", line 420, in place_order
    background_tasks.add_task(update_user_cache)
                              ^^^^^^^^^^^^^^^^^
UnboundLocalError: cannot access local variable 'update_user_cache' where it is not associated with a value
2025-07-03 22:39:41,140 - ERROR - error - Error in place_order: 1 validation error for OrderResponse
status
  Input should be a valid string [type=string_type, input_value=None, input_type=NoneType]
    For further information visit https://errors.pydantic.dev/2.11/v/string_type
Traceback (most recent call last):
  File "C:\Users\Dhanush\FASTAPI\app\api\v1\endpoints\orders.py", line 472, in place_order
    return OrderResponse(
        id=new_order.id,
    ...<26 lines>...
        updated_at=new_order.updated_at
    )
  File "C:\Users\Dhanush\AppData\Local\Programs\Python\Python313\Lib\site-packages\pydantic\main.py", line 253, in __init__
    validated_self = self.__pydantic_validator__.validate_python(data, self_instance=self)
pydantic_core._pydantic_core.ValidationError: 1 validation error for OrderResponse
status
  Input should be a valid string [type=string_type, input_value=None, input_type=NoneType]
    For further information visit https://errors.pydantic.dev/2.11/v/string_type
2025-07-04 00:32:27,503 - ERROR - error - Error in place_order: (pymysql.err.IntegrityError) (1452, 'Cannot add or update a child row: a foreign key constraint fails (`u436589492_forex`.`user_orders`, CONSTRAINT `user_orders_ibfk_1` FOREIGN KEY (`order_user_id`) REFERENCES `users` (`id`))')
[SQL: INSERT INTO user_orders (status, order_id, order_user_id, order_company_name, order_type, order_status, order_price, order_quantity, contract_value, margin, stop_loss, take_profit, close_price, net_profit, swap, commission, cancel_message, close_message, cancel_id, close_id, modify_id, stoploss_id, takeprofit_id, stoploss_cancel_id, takeprofit_cancel_id) VALUES (%s, %s, %s, %s, %s, %s, %s, %s, %s, %s, %s, %s, %s, %s, %s, %s, %s, %s, %s, %s, %s, %s, %s, %s, %s)]
[parameters: (None, '3472320865', 1, 'AUDCHF', 'BUY', 'OPEN', Decimal('0.52061205600000'), Decimal('0.01'), Decimal('520.61'), Decimal('6.562870027460761343309903509'), None, None, None, None, None, Decimal('0.10'), None, None, None, None, None, None, None, None, None)]
(Background on this error at: https://sqlalche.me/e/20/gkpj)
Traceback (most recent call last):
  File "C:\Users\Dhanush\FASTAPI\venv\Lib\site-packages\sqlalchemy\engine\base.py", line 1963, in _exec_single_context
    self.dialect.do_execute(
    ~~~~~~~~~~~~~~~~~~~~~~~^
        cursor, str_statement, effective_parameters, context
        ^^^^^^^^^^^^^^^^^^^^^^^^^^^^^^^^^^^^^^^^^^^^^^^^^^^^
    )
    ^
  File "C:\Users\Dhanush\FASTAPI\venv\Lib\site-packages\sqlalchemy\engine\default.py", line 943, in do_execute
    cursor.execute(statement, parameters)
    ~~~~~~~~~~~~~~^^^^^^^^^^^^^^^^^^^^^^^
  File "C:\Users\Dhanush\FASTAPI\venv\Lib\site-packages\sqlalchemy\dialects\mysql\aiomysql.py", line 97, in execute
    return self.await_(self._execute_async(operation, parameters))
           ~~~~~~~~~~~^^^^^^^^^^^^^^^^^^^^^^^^^^^^^^^^^^^^^^^^^^^^
  File "C:\Users\Dhanush\FASTAPI\venv\Lib\site-packages\sqlalchemy\util\_concurrency_py3k.py", line 132, in await_only
    return current.parent.switch(awaitable)  # type: ignore[no-any-return,attr-defined] # noqa: E501
           ~~~~~~~~~~~~~~~~~~~~~^^^^^^^^^^^
  File "C:\Users\Dhanush\FASTAPI\venv\Lib\site-packages\sqlalchemy\util\_concurrency_py3k.py", line 196, in greenlet_spawn
    value = await result
            ^^^^^^^^^^^^
  File "C:\Users\Dhanush\FASTAPI\venv\Lib\site-packages\sqlalchemy\dialects\mysql\aiomysql.py", line 106, in _execute_async
    result = await self._cursor.execute(operation, parameters)
             ^^^^^^^^^^^^^^^^^^^^^^^^^^^^^^^^^^^^^^^^^^^^^^^^^
  File "C:\Users\Dhanush\FASTAPI\venv\Lib\site-packages\aiomysql\cursors.py", line 239, in execute
    await self._query(query)
  File "C:\Users\Dhanush\FASTAPI\venv\Lib\site-packages\aiomysql\cursors.py", line 457, in _query
    await conn.query(q)
  File "C:\Users\Dhanush\FASTAPI\venv\Lib\site-packages\aiomysql\connection.py", line 469, in query
    await self._read_query_result(unbuffered=unbuffered)
  File "C:\Users\Dhanush\FASTAPI\venv\Lib\site-packages\aiomysql\connection.py", line 683, in _read_query_result
    await result.read()
  File "C:\Users\Dhanush\FASTAPI\venv\Lib\site-packages\aiomysql\connection.py", line 1164, in read
    first_packet = await self.connection._read_packet()
                   ^^^^^^^^^^^^^^^^^^^^^^^^^^^^^^^^^^^^
  File "C:\Users\Dhanush\FASTAPI\venv\Lib\site-packages\aiomysql\connection.py", line 652, in _read_packet
    packet.raise_for_error()
    ~~~~~~~~~~~~~~~~~~~~~~^^
  File "C:\Users\Dhanush\FASTAPI\venv\Lib\site-packages\pymysql\protocol.py", line 219, in raise_for_error
    err.raise_mysql_exception(self._data)
    ~~~~~~~~~~~~~~~~~~~~~~~~~^^^^^^^^^^^^
  File "C:\Users\Dhanush\FASTAPI\venv\Lib\site-packages\pymysql\err.py", line 150, in raise_mysql_exception
    raise errorclass(errno, errval)
pymysql.err.IntegrityError: (1452, 'Cannot add or update a child row: a foreign key constraint fails (`u436589492_forex`.`user_orders`, CONSTRAINT `user_orders_ibfk_1` FOREIGN KEY (`order_user_id`) REFERENCES `users` (`id`))')

The above exception was the direct cause of the following exception:

Traceback (most recent call last):
  File "C:\Users\Dhanush\FASTAPI\app\api\v1\endpoints\orders.py", line 414, in place_order
    new_order = await crud_order.create_user_order(db=db, order_data=order_create_data.dict())
                ^^^^^^^^^^^^^^^^^^^^^^^^^^^^^^^^^^^^^^^^^^^^^^^^^^^^^^^^^^^^^^^^^^^^^^^^^^^^^^
  File "C:\Users\Dhanush\FASTAPI\app\crud\crud_order.py", line 386, in create_user_order
    raise e
  File "C:\Users\Dhanush\FASTAPI\app\crud\crud_order.py", line 380, in create_user_order
    await db.commit()
  File "C:\Users\Dhanush\FASTAPI\venv\Lib\site-packages\sqlalchemy\ext\asyncio\session.py", line 1014, in commit
    await greenlet_spawn(self.sync_session.commit)
  File "C:\Users\Dhanush\FASTAPI\venv\Lib\site-packages\sqlalchemy\util\_concurrency_py3k.py", line 203, in greenlet_spawn
    result = context.switch(value)
  File "C:\Users\Dhanush\FASTAPI\venv\Lib\site-packages\sqlalchemy\orm\session.py", line 2032, in commit
    trans.commit(_to_root=True)
    ~~~~~~~~~~~~^^^^^^^^^^^^^^^
  File "<string>", line 2, in commit
  File "C:\Users\Dhanush\FASTAPI\venv\Lib\site-packages\sqlalchemy\orm\state_changes.py", line 139, in _go
    ret_value = fn(self, *arg, **kw)
  File "C:\Users\Dhanush\FASTAPI\venv\Lib\site-packages\sqlalchemy\orm\session.py", line 1313, in commit
    self._prepare_impl()
    ~~~~~~~~~~~~~~~~~~^^
  File "<string>", line 2, in _prepare_impl
  File "C:\Users\Dhanush\FASTAPI\venv\Lib\site-packages\sqlalchemy\orm\state_changes.py", line 139, in _go
    ret_value = fn(self, *arg, **kw)
  File "C:\Users\Dhanush\FASTAPI\venv\Lib\site-packages\sqlalchemy\orm\session.py", line 1288, in _prepare_impl
    self.session.flush()
    ~~~~~~~~~~~~~~~~~~^^
  File "C:\Users\Dhanush\FASTAPI\venv\Lib\site-packages\sqlalchemy\orm\session.py", line 4345, in flush
    self._flush(objects)
    ~~~~~~~~~~~^^^^^^^^^
  File "C:\Users\Dhanush\FASTAPI\venv\Lib\site-packages\sqlalchemy\orm\session.py", line 4480, in _flush
    with util.safe_reraise():
         ~~~~~~~~~~~~~~~~~^^
  File "C:\Users\Dhanush\FASTAPI\venv\Lib\site-packages\sqlalchemy\util\langhelpers.py", line 224, in __exit__
    raise exc_value.with_traceback(exc_tb)
  File "C:\Users\Dhanush\FASTAPI\venv\Lib\site-packages\sqlalchemy\orm\session.py", line 4441, in _flush
    flush_context.execute()
    ~~~~~~~~~~~~~~~~~~~~~^^
  File "C:\Users\Dhanush\FASTAPI\venv\Lib\site-packages\sqlalchemy\orm\unitofwork.py", line 466, in execute
    rec.execute(self)
    ~~~~~~~~~~~^^^^^^
  File "C:\Users\Dhanush\FASTAPI\venv\Lib\site-packages\sqlalchemy\orm\unitofwork.py", line 642, in execute
    util.preloaded.orm_persistence.save_obj(
    ~~~~~~~~~~~~~~~~~~~~~~~~~~~~~~~~~~~~~~~^
        self.mapper,
        ^^^^^^^^^^^^
        uow.states_for_mapper_hierarchy(self.mapper, False, False),
        ^^^^^^^^^^^^^^^^^^^^^^^^^^^^^^^^^^^^^^^^^^^^^^^^^^^^^^^^^^^
        uow,
        ^^^^
    )
    ^
  File "C:\Users\Dhanush\FASTAPI\venv\Lib\site-packages\sqlalchemy\orm\persistence.py", line 93, in save_obj
    _emit_insert_statements(
    ~~~~~~~~~~~~~~~~~~~~~~~^
        base_mapper,
        ^^^^^^^^^^^^
    ...<3 lines>...
        insert,
        ^^^^^^^
    )
    ^
  File "C:\Users\Dhanush\FASTAPI\venv\Lib\site-packages\sqlalchemy\orm\persistence.py", line 1233, in _emit_insert_statements
    result = connection.execute(
        statement,
        params,
        execution_options=execution_options,
    )
  File "C:\Users\Dhanush\FASTAPI\venv\Lib\site-packages\sqlalchemy\engine\base.py", line 1415, in execute
    return meth(
        self,
        distilled_parameters,
        execution_options or NO_OPTIONS,
    )
  File "C:\Users\Dhanush\FASTAPI\venv\Lib\site-packages\sqlalchemy\sql\elements.py", line 523, in _execute_on_connection
    return connection._execute_clauseelement(
           ~~~~~~~~~~~~~~~~~~~~~~~~~~~~~~~~~^
        self, distilled_params, execution_options
        ^^^^^^^^^^^^^^^^^^^^^^^^^^^^^^^^^^^^^^^^^
    )
    ^
  File "C:\Users\Dhanush\FASTAPI\venv\Lib\site-packages\sqlalchemy\engine\base.py", line 1637, in _execute_clauseelement
    ret = self._execute_context(
        dialect,
    ...<8 lines>...
        cache_hit=cache_hit,
    )
  File "C:\Users\Dhanush\FASTAPI\venv\Lib\site-packages\sqlalchemy\engine\base.py", line 1842, in _execute_context
    return self._exec_single_context(
           ~~~~~~~~~~~~~~~~~~~~~~~~~^
        dialect, context, statement, parameters
        ^^^^^^^^^^^^^^^^^^^^^^^^^^^^^^^^^^^^^^^
    )
    ^
  File "C:\Users\Dhanush\FASTAPI\venv\Lib\site-packages\sqlalchemy\engine\base.py", line 1982, in _exec_single_context
    self._handle_dbapi_exception(
    ~~~~~~~~~~~~~~~~~~~~~~~~~~~~^
        e, str_statement, effective_parameters, cursor, context
        ^^^^^^^^^^^^^^^^^^^^^^^^^^^^^^^^^^^^^^^^^^^^^^^^^^^^^^^
    )
    ^
  File "C:\Users\Dhanush\FASTAPI\venv\Lib\site-packages\sqlalchemy\engine\base.py", line 2351, in _handle_dbapi_exception
    raise sqlalchemy_exception.with_traceback(exc_info[2]) from e
  File "C:\Users\Dhanush\FASTAPI\venv\Lib\site-packages\sqlalchemy\engine\base.py", line 1963, in _exec_single_context
    self.dialect.do_execute(
    ~~~~~~~~~~~~~~~~~~~~~~~^
        cursor, str_statement, effective_parameters, context
        ^^^^^^^^^^^^^^^^^^^^^^^^^^^^^^^^^^^^^^^^^^^^^^^^^^^^
    )
    ^
  File "C:\Users\Dhanush\FASTAPI\venv\Lib\site-packages\sqlalchemy\engine\default.py", line 943, in do_execute
    cursor.execute(statement, parameters)
    ~~~~~~~~~~~~~~^^^^^^^^^^^^^^^^^^^^^^^
  File "C:\Users\Dhanush\FASTAPI\venv\Lib\site-packages\sqlalchemy\dialects\mysql\aiomysql.py", line 97, in execute
    return self.await_(self._execute_async(operation, parameters))
           ~~~~~~~~~~~^^^^^^^^^^^^^^^^^^^^^^^^^^^^^^^^^^^^^^^^^^^^
  File "C:\Users\Dhanush\FASTAPI\venv\Lib\site-packages\sqlalchemy\util\_concurrency_py3k.py", line 132, in await_only
    return current.parent.switch(awaitable)  # type: ignore[no-any-return,attr-defined] # noqa: E501
           ~~~~~~~~~~~~~~~~~~~~~^^^^^^^^^^^
  File "C:\Users\Dhanush\FASTAPI\venv\Lib\site-packages\sqlalchemy\util\_concurrency_py3k.py", line 196, in greenlet_spawn
    value = await result
            ^^^^^^^^^^^^
  File "C:\Users\Dhanush\FASTAPI\venv\Lib\site-packages\sqlalchemy\dialects\mysql\aiomysql.py", line 106, in _execute_async
    result = await self._cursor.execute(operation, parameters)
             ^^^^^^^^^^^^^^^^^^^^^^^^^^^^^^^^^^^^^^^^^^^^^^^^^
  File "C:\Users\Dhanush\FASTAPI\venv\Lib\site-packages\aiomysql\cursors.py", line 239, in execute
    await self._query(query)
  File "C:\Users\Dhanush\FASTAPI\venv\Lib\site-packages\aiomysql\cursors.py", line 457, in _query
    await conn.query(q)
  File "C:\Users\Dhanush\FASTAPI\venv\Lib\site-packages\aiomysql\connection.py", line 469, in query
    await self._read_query_result(unbuffered=unbuffered)
  File "C:\Users\Dhanush\FASTAPI\venv\Lib\site-packages\aiomysql\connection.py", line 683, in _read_query_result
    await result.read()
  File "C:\Users\Dhanush\FASTAPI\venv\Lib\site-packages\aiomysql\connection.py", line 1164, in read
    first_packet = await self.connection._read_packet()
                   ^^^^^^^^^^^^^^^^^^^^^^^^^^^^^^^^^^^^
  File "C:\Users\Dhanush\FASTAPI\venv\Lib\site-packages\aiomysql\connection.py", line 652, in _read_packet
    packet.raise_for_error()
    ~~~~~~~~~~~~~~~~~~~~~~^^
  File "C:\Users\Dhanush\FASTAPI\venv\Lib\site-packages\pymysql\protocol.py", line 219, in raise_for_error
    err.raise_mysql_exception(self._data)
    ~~~~~~~~~~~~~~~~~~~~~~~~~^^^^^^^^^^^^
  File "C:\Users\Dhanush\FASTAPI\venv\Lib\site-packages\pymysql\err.py", line 150, in raise_mysql_exception
    raise errorclass(errno, errval)
sqlalchemy.exc.IntegrityError: (pymysql.err.IntegrityError) (1452, 'Cannot add or update a child row: a foreign key constraint fails (`u436589492_forex`.`user_orders`, CONSTRAINT `user_orders_ibfk_1` FOREIGN KEY (`order_user_id`) REFERENCES `users` (`id`))')
[SQL: INSERT INTO user_orders (status, order_id, order_user_id, order_company_name, order_type, order_status, order_price, order_quantity, contract_value, margin, stop_loss, take_profit, close_price, net_profit, swap, commission, cancel_message, close_message, cancel_id, close_id, modify_id, stoploss_id, takeprofit_id, stoploss_cancel_id, takeprofit_cancel_id) VALUES (%s, %s, %s, %s, %s, %s, %s, %s, %s, %s, %s, %s, %s, %s, %s, %s, %s, %s, %s, %s, %s, %s, %s, %s, %s)]
[parameters: (None, '3472320865', 1, 'AUDCHF', 'BUY', 'OPEN', Decimal('0.52061205600000'), Decimal('0.01'), Decimal('520.61'), Decimal('6.562870027460761343309903509'), None, None, None, None, None, Decimal('0.10'), None, None, None, None, None, None, None, None, None)]
(Background on this error at: https://sqlalche.me/e/20/gkpj)
2025-07-04 03:06:26,617 - ERROR - error - Error in place_order: name 'is_barclays_live_user' is not defined
Traceback (most recent call last):
  File "C:\Users\Dhanush\FASTAPI\app\api\v1\endpoints\orders.py", line 365, in place_order
    is_barclays_live_user(current_user, db, redis_client),
    ^^^^^^^^^^^^^^^^^^^^^
NameError: name 'is_barclays_live_user' is not defined
2025-07-04 03:06:49,213 - ERROR - error - Error in place_order: name 'is_barclays_live_user' is not defined
Traceback (most recent call last):
  File "C:\Users\Dhanush\FASTAPI\app\api\v1\endpoints\orders.py", line 365, in place_order
    is_barclays_live_user(current_user, db, redis_client),
    ^^^^^^^^^^^^^^^^^^^^^
NameError: name 'is_barclays_live_user' is not defined
2025-07-04 06:46:11,542 - ERROR - error - Error in service_provider_order_execution: 400: Invalid status transition from PROCESSING to PROCESSING
Traceback (most recent call last):
  File "C:\Users\Dhanush\FASTAPI\app\api\v1\endpoints\orders.py", line 3386, in service_provider_order_execution
    raise HTTPException(status_code=400, detail=error_msg)
fastapi.exceptions.HTTPException: 400: Invalid status transition from PROCESSING to PROCESSING
